Workbook

Sheet Resumo
A1: Batalha Naval — Plano para nota 10
A2: Preencha os nomes nas células amarelas. Edite o andamento na aba Tarefas; esta aba atualiza sozinha.
A4: 1. Equipe e andamento das tarefas
A5: Código | B5: Nome (preencher) | C5: Foco | D5: Total | E5: Feito | F5: Revisar e ajustar | G5: A fazer | H5: % feito
A6: P1 | B6: Nome do participante 1 | C6: Interface gráfica | D6: =COUNTIF(Tarefas!$C$5:$C$200,$A6) -> 16 | E6: =COUNTIFS(Tarefas!$C$5:$C$200,$A6,Tarefas!$G$5:$G$200,E$5) -> 1 | F6: =COUNTIFS(Tarefas!$C$5:$C$200,$A6,Tarefas!$G$5:$G$200,F$5) -> 5 | G6: =COUNTIFS(Tarefas!$C$5:$C$200,$A6,Tarefas!$G$5:$G$200,G$5) -> 10 | H6: =IF(D6=0,0,E6/D6) -> 0.0625
A7: P2 | B7: Nome do participante 2 | C7: Lógica do jogo e IA | D7: =COUNTIF(Tarefas!$C$5:$C$200,$A7) -> 13 | E7: =COUNTIFS(Tarefas!$C$5:$C$200,$A7,Tarefas!$G$5:$G$200,E$5) -> 0 | F7: =COUNTIFS(Tarefas!$C$5:$C$200,$A7,Tarefas!$G$5:$G$200,F$5) -> 6 | G7: =COUNTIFS(Tarefas!$C$5:$C$200,$A7,Tarefas!$G$5:$G$200,G$5) -> 7 | H7: =IF(D7=0,0,E7/D7) -> 0
A8: P3 | B8: Nome do participante 3 | C8: Persistência e visualização | D8: =COUNTIF(Tarefas!$C$5:$C$200,$A8) -> 12 | E8: =COUNTIFS(Tarefas!$C$5:$C$200,$A8,Tarefas!$G$5:$G$200,E$5) -> 1 | F8: =COUNTIFS(Tarefas!$C$5:$C$200,$A8,Tarefas!$G$5:$G$200,F$5) -> 0 | G8: =COUNTIFS(Tarefas!$C$5:$C$200,$A8,Tarefas!$G$5:$G$200,G$5) -> 11 | H8: =IF(D8=0,0,E8/D8) -> 0.083333333
A9: Todos | B9: — | C9: Entrega, registros e apresentação | D9: =COUNTIF(Tarefas!$C$5:$C$200,$A9) -> 7 | E9: =COUNTIFS(Tarefas!$C$5:$C$200,$A9,Tarefas!$G$5:$G$200,E$5) -> 0 | F9: =COUNTIFS(Tarefas!$C$5:$C$200,$A9,Tarefas!$G$5:$G$200,F$5) -> 0 | G9: =COUNTIFS(Tarefas!$C$5:$C$200,$A9,Tarefas!$G$5:$G$200,G$5) -> 7 | H9: =IF(D9=0,0,E9/D9) -> 0
A10: Total | D10: =SUM(D6:D9) -> 48 | E10: =SUM(E6:E9) -> 2 | F10: =SUM(F6:F9) -> 11 | G10: =SUM(G6:G9) -> 35 | H10: =IF(D10=0,0,E10/D10) -> 0.041666667
A12: 2. Cronograma e andamento por etapa
A13: Etapa | B13: Data | C13: Peso na nota individual | D13: Dias restantes | E13: Total | F13: Feito | G13: Revisar e ajustar | H13: A fazer
A14: Sprint 1 | B14: 46324 | C14: 0.2 | D14: =MAX(0,B14-TODAY()) -> 4 | E14: =COUNTIF(Tarefas!$B$5:$B$200,$A14) -> 17 | F14: =COUNTIFS(Tarefas!$B$5:$B$200,$A14,Tarefas!$G$5:$G$200,$E$5) -> 2 | G14: =COUNTIFS(Tarefas!$B$5:$B$200,$A14,Tarefas!$G$5:$G$200,$F$5) -> 10 | H14: =COUNTIFS(Tarefas!$B$5:$B$200,$A14,Tarefas!$G$5:$G$200,$G$5) -> 5
A15: Sprint 2 | B15: 46331 | C15: 0.2 | D15: =MAX(0,B15-TODAY()) -> 11 | E15: =COUNTIF(Tarefas!$B$5:$B$200,$A15) -> 13 | F15: =COUNTIFS(Tarefas!$B$5:$B$200,$A15,Tarefas!$G$5:$G$200,$E$5) -> 0 | G15: =COUNTIFS(Tarefas!$B$5:$B$200,$A15,Tarefas!$G$5:$G$200,$F$5) -> 0 | H15: =COUNTIFS(Tarefas!$B$5:$B$200,$A15,Tarefas!$G$5:$G$200,$G$5) -> 13
A16: Sprint 3 | B16: 46338 | C16: 0.2 | D16: =MAX(0,B16-TODAY()) -> 18 | E16: =COUNTIF(Tarefas!$B$5:$B$200,$A16) -> 17 | F16: =COUNTIFS(Tarefas!$B$5:$B$200,$A16,Tarefas!$G$5:$G$200,$E$5) -> 0 | G16: =COUNTIFS(Tarefas!$B$5:$B$200,$A16,Tarefas!$G$5:$G$200,$F$5) -> 1 | H16: =COUNTIFS(Tarefas!$B$5:$B$200,$A16,Tarefas!$G$5:$G$200,$G$5) -> 16
A17: Final | B17: 46345 | C17: 0.4 | D17: =MAX(0,B17-TODAY()) -> 25 | E17: =COUNTIF(Tarefas!$B$5:$B$200,$A17) -> 1 | F17: =COUNTIFS(Tarefas!$B$5:$B$200,$A17,Tarefas!$G$5:$G$200,$E$5) -> 0 | G17: =COUNTIFS(Tarefas!$B$5:$B$200,$A17,Tarefas!$G$5:$G$200,$F$5) -> 0 | H17: =COUNTIFS(Tarefas!$B$5:$B$200,$A17,Tarefas!$G$5:$G$200,$G$5) -> 1
A19: 3. Pontuação da rubrica (meta: 10,0)
A20: Obrigatórios (70%) | B20: =SUMIFS(Rubrica!$C$5:$C$15,Rubrica!$B$5:$B$15,"Obrigatório") -> 7 | C20: Soma dos critérios obrigatórios da rubrica
A21: Opcionais planejados | B21: =SUMIFS(Rubrica!$C$5:$C$15,Rubrica!$B$5:$B$15,"Opcional",Rubrica!$D$5:$D$15,"Sim") -> 3.5 | C21: Interface gráfica + persistência + visualização (tema do projeto)
A22: Opcionais necessários (30%) | B22: 3 | C22: 30% de 10,0, conforme a seção 2 do enunciado (dado do enunciado)
A23: Nota máxima do projeto | B23: 10 | C23: Limite informado no enunciado: a nota máxima é 10,0
A24: Pontuação potencial | B24: =MIN(B23,B20+B21) -> 10 | C24: Se todos os critérios planejados forem 'Completo'
A25: Situação dos opcionais | B25: =IF(B21>=B22,"Meta de opcionais coberta","Faltam opcionais") -> Meta de opcionais coberta | C25: A margem acima de 3,0 protege contra um critério sair como 'Parcial'

Sheet Tarefas
A1: Tarefas do projeto — Batalha Naval
A2: Edite: Sprint, Responsável, Status, Prioridade e Observações (use as listas suspensas). Os números das outras abas se atualizam sozinhos. Linhas novas: até a linha 200.
A4: ID | B4: Sprint | C4: Responsável | D4: Critério da rubrica | E4: Atividade | F4: Arquivo | G4: Status | H4: Prioridade | I4: Observações
A5: T01 | B5: Sprint 1 | C5: P2 | D5: Entrega e execução | E5: Criar repositório no GitHub, adicionar os integrantes e dar acesso à professora | F5: GitHub | G5: A fazer | H5: Alta | I5: Cada integrante trabalha em commits/branch próprios para a autoria ficar comprovável
A6: T02 | B6: Sprint 1 | C6: P1 | D6: Entrega e execução | E6: Estrutura de pastas (batalha_naval/, registros_individuais/) e main.py | F6: main.py | G6: Feito | H6: Média | I6: Esqueleto já criado e compilando
A7: T03 | B7: Sprint 1 | C7: P3 | D7: Entrega e execução | E7: requirements.txt (matplotlib) e .gitignore | F7: requirements.txt | G7: Feito | H7: Baixa | I7: Conferir a versão do matplotlib ao testar em máquina limpa
A8: T04 | B8: Sprint 3 | C8: P2 | D8: Entrega e execução | E8: README.md completo: descrição, funcionalidades, requisitos, bibliotecas, instalação e execução | F8: README.md | G8: Revisar e ajustar | H8: Alta | I8: Existe um rascunho; cada integrante complementa a sua parte
A9: T05 | B9: Sprint 3 | C9: Todos | D9: Entrega e execução | E9: Testar em outro computador/ambiente limpo (venv novo) seguindo apenas o README | F9: — | G9: A fazer | H9: Alta | I9: Condição eliminatória: se não executar, a nota do trabalho é 0,0
A10: T06 | B10: Sprint 3 | C10: Todos | D10: Entrega e execução | E10: Conferir ausência de caminhos absolutos, credenciais e arquivos que só existam em um computador | F10: — | G10: A fazer | H10: Alta
A11: T07 | B11: Sprint 1 | C11: Todos | D11: Registro individual e apresentação | E11: Registro Individual da Sprint 1 (implementações, testes, estudos, planejamento, com evidências e commits) | F11: nome_completo_do_estudante.docx | G11: A fazer | H11: Alta | I11: Evidências concretas: commits, trechos de código, fontes estudadas. Evitar frases genéricas
A12: T08 | B12: Sprint 2 | C12: Todos | D12: Registro individual e apresentação | E12: Registro Individual da Sprint 2 | F12: nome_completo_do_estudante.docx | G12: A fazer | H12: Alta
A13: T09 | B13: Sprint 3 | C13: Todos | D13: Registro individual e apresentação | E13: Registro Individual da Sprint 3 | F13: nome_completo_do_estudante.docx | G13: A fazer | H13: Alta
A14: T10 | B14: Sprint 3 | C14: Todos | D14: Registro individual e apresentação | E14: Exportar os registros em PDF (nome_completo_do_estudante.pdf) para registros_individuais/ | F14: registros_individuais/ | G14: A fazer | H14: Alta
A15: T11 | B15: Final | C15: Todos | D15: Registro individual e apresentação | E15: Preparar a apresentação: cada um explica suas contribuições e decisões de implementação | F15: — | G15: A fazer | H15: Alta | I15: Vale 40% da nota individual
A16: T12 | B16: Sprint 1 | C16: P1 | D16: Interface gráfica | E16: Janela principal e troca de telas (App.mostrar) | F16: interface.py | G16: Revisar e ajustar | H16: Alta | I16: Código escrito mas ainda NÃO executado: rodar e validar
A17: T13 | B17: Sprint 1 | C17: P1 | D17: Interface gráfica | E17: Widget TabuleiroCanvas: desenho da grade, hover e clique | F17: interface.py | G17: Revisar e ajustar | H17: Alta | I17: Validar coordenadas (A–J / 1–10) e cores
A18: T14 | B18: Sprint 1 | C18: P1 | D18: Interface gráfica | E18: Tela de menu | F18: interface.py | G18: Revisar e ajustar | H18: Média
A19: T15 | B19: Sprint 1 | C19: P1 | D19: Interação com o usuário | E19: Tela de posicionamento: prévia, girar, aleatório, limpar e iniciar | F19: interface.py | G19: Revisar e ajustar | H19: Alta | I19: Testar botão direito no seu sistema (Windows/Linux/macOS)
A20: T16 | B20: Sprint 1 | C20: P1 | D20: Controle do fluxo de execução | E20: Tela de batalha: turnos jogador/IA, log de jogadas e fim de partida | F20: interface.py | G20: Revisar e ajustar | H20: Alta | I20: Jogar uma partida completa; checar bloqueio de cliques durante a vez da IA
A21: T17 | B21: Sprint 1 | C21: P1 | D21: Interação com o usuário | E21: Tela de nome do jogador com validação (vazio, tamanho máximo) | F21: interface.py | G21: A fazer | H21: Alta | I21: O nome entra no histórico e no ranking
A22: T18 | B22: Sprint 2 | C22: P1 | D22: Controle do fluxo de execução | E22: Desistir/voltar ao menu com confirmação; desistência conta como derrota no histórico | F22: interface.py | G22: A fazer | H22: Média
A23: T19 | B23: Sprint 2 | C23: P1 | D23: Interface gráfica | E23: Painel de frota: mostrar quais navios já foram afundados (jogador e inimigo) | F23: interface.py | G23: A fazer | H23: Média | I23: Depende de P2 expor os navios afundados
A24: T20 | B24: Sprint 2 | C24: P1 | D24: Modularização e organização do código | E24: Dividir interface.py em um arquivo por tela (menu, posicionamento, batalha, estatísticas) | F24: interface/ | G24: A fazer | H24: Média | I24: Fazer só depois que as telas estiverem estáveis
A25: T21 | B25: Sprint 2 | C25: P1 | D25: Confiabilidade e tratamento de situações previstas | E25: Mensagem de erro amigável se o salvamento da partida falhar | F25: interface.py | G25: A fazer | H25: Média | I25: Usa a função de P3
A26: T22 | B26: Sprint 3 | C26: P1 | D26: Visualização de informações | E26: Tela de estatísticas: tabela de histórico (ttk.Treeview) e botões para alternar gráficos | F26: interface.py | G26: A fazer | H26: Alta | I26: Depende do histórico de P3
A27: T23 | B27: Sprint 3 | C27: P1 | D27: Visualização de informações | E27: Embutir os gráficos de estatisticas.py na tela (FigureCanvasTkAgg) | F27: interface.py | G27: A fazer | H27: Alta | I27: Usa as funções de P3 que devolvem Figure
A28: T24 | B28: Sprint 3 | C28: P1 | D28: Confiabilidade e tratamento de situações previstas | E28: Tratar o fechamento da janela no meio da partida | F28: interface.py | G28: A fazer | H28: Média
A29: T25 | B29: Sprint 3 | C29: P1 | D29: Interface gráfica | E29: Checklist de testes manuais de todas as telas e botões | F29: — | G29: A fazer | H29: Alta | I29: Registrar resultados no Registro Individual
A30: T26 | B30: Sprint 3 | C30: P1 | D30: Interface gráfica | E30: Polimento visual (cores, fontes, alinhamento) | F30: interface.py | G30: A fazer | H30: Baixa
A31: T27 | B31: Sprint 1 | C31: P2 | D31: Organização e manipulação de dados | E31: Constantes e estruturas: grade (lista de listas), lista de navios, estados da célula | F31: modelo.py | G31: Revisar e ajustar | H31: Alta | I31: Revisar e saber justificar a escolha das estruturas
A32: T28 | B32: Sprint 1 | C32: P2 | D32: Processamento e regras de negócio | E32: Classe Tabuleiro: posicionar, validar limites/sobreposição e atirar | F32: modelo.py | G32: Revisar e ajustar | H32: Alta | I32: Versão mínima criada; revisar casos de borda
A33: T29 | B33: Sprint 1 | C33: P2 | D33: Processamento e regras de negócio | E33: Posicionamento aleatório da frota | F33: modelo.py | G33: Revisar e ajustar | H33: Média | I33: Confirmar que o laço sempre termina
A34: T30 | B34: Sprint 1 | C34: P2 | D34: Processamento e regras de negócio | E34: Detecção de navio afundado e fim de jogo | F34: modelo.py | G34: Revisar e ajustar | H34: Alta
A35: T31 | B35: Sprint 1 | C35: P2 | D35: Processamento e regras de negócio | E35: IA: tiro aleatório + caça nos vizinhos após acerto | F35: modelo.py | G35: Revisar e ajustar | H35: Média | I35: Smoke test: IA afundou uma frota em 79 tiros. Faltam testes completos
A36: T32 | B36: Sprint 2 | C36: P2 | D36: Confiabilidade e tratamento de situações previstas | E36: Testes automatizados (unittest): posicionamento inválido, tiro repetido, afundar, vitória | F36: tests/test_modelo.py | G36: A fazer | H36: Alta | I36: Evidência ótima para o registro (Testes e investigações)
A37: T33 | B37: Sprint 2 | C37: P2 | D37: Confiabilidade e tratamento de situações previstas | E37: Validar entradas de atirar/posicionar (índices fora do tabuleiro, tipos inválidos) sem quebrar o programa | F37: modelo.py | G37: A fazer | H37: Média
A38: T34 | B38: Sprint 2 | C38: P2 | D38: Controle do fluxo de execução | E38: Criar classe Partida (turnos, vencedor, contadores de tiros/acertos/duração), tirando essa lógica da interface | F38: modelo.py | G38: A fazer | H38: Alta | I38: Combinar a assinatura com P1 e P3 antes de implementar
A39: T35 | B39: Sprint 2 | C39: P2 | D39: Processamento e regras de negócio | E39: Melhorar a IA: continuar na direção do acerto e tiros em paridade (nível único) | F39: modelo.py | G39: A fazer | H39: Baixa | I39: Sem modos de dificuldade, conforme decisão da equipe
A40: T36 | B40: Sprint 3 | C40: P2 | D40: Confiabilidade e tratamento de situações previstas | E40: Simulação de 1000 partidas (IA x tabuleiros aleatórios) para garantir que nunca trava | F40: tests/test_modelo.py | G40: A fazer | H40: Média
A41: T37 | B41: Sprint 3 | C41: P2 | D41: Modularização e organização do código | E41: Revisar funções: docstrings, responsabilidade única e remoção de repetições | F41: modelo.py | G41: A fazer | H41: Média
...

Sheet Rubrica
A1: Rubrica de avaliação × plano da equipe
A2: Peso de 'Revisar e ajustar' no progresso (Feito = 1, A fazer = 0): | F2: 0.5 | G2: Premissa da equipe: ajuste se quiser outro peso.
A4: Critério | B4: Tipo | C4: Pontos máx. | D4: Planejado? | E4: Responsável principal | F4: Tarefas | G4: Feito | H4: Revisar e ajustar | I4: A fazer | J4: Progresso | K4: O que a rubrica pede para 'Completo'
A5: Interação com o usuário | B5: Obrigatório | C5: 1 | D5: Sim | E5: P1 | F5: =COUNTIF(Tarefas!$D$5:$D$200,$A5) -> 2 | G5: =COUNTIFS(Tarefas!$D$5:$D$200,$A5,Tarefas!$G$5:$G$200,G$4) -> 0 | H5: =COUNTIFS(Tarefas!$D$5:$D$200,$A5,Tarefas!$G$5:$G$200,H$4) -> 1 | I5: =COUNTIFS(Tarefas!$D$5:$D$200,$A5,Tarefas!$G$5:$G$200,I$4) -> 1 | J5: =IF(F5=0,"—",(G5+$F$2*H5)/F5) -> 0.25 | K5: Interação clara e funcional; as escolhas do usuário (nome, cliques) influenciam o programa
A6: Processamento e regras de negócio | B6: Obrigatório | C6: 1.5 | D6: Sim | E6: P2 | F6: =COUNTIF(Tarefas!$D$5:$D$200,$A6) -> 5 | G6: =COUNTIFS(Tarefas!$D$5:$D$200,$A6,Tarefas!$G$5:$G$200,G$4) -> 0 | H6: =COUNTIFS(Tarefas!$D$5:$D$200,$A6,Tarefas!$G$5:$G$200,H$4) -> 4 | I6: =COUNTIFS(Tarefas!$D$5:$D$200,$A6,Tarefas!$G$5:$G$200,I$4) -> 1 | J6: =IF(F6=0,"—",(G6+$F$2*H6)/F6) -> 0.4 | K6: Regras corretas em diferentes condições, com resultados coerentes
A7: Controle do fluxo de execução | B7: Obrigatório | C7: 1 | D7: Sim | E7: P2 + P1 | F7: =COUNTIF(Tarefas!$D$5:$D$200,$A7) -> 3 | G7: =COUNTIFS(Tarefas!$D$5:$D$200,$A7,Tarefas!$G$5:$G$200,G$4) -> 0 | H7: =COUNTIFS(Tarefas!$D$5:$D$200,$A7,Tarefas!$G$5:$G$200,H$4) -> 1 | I7: =COUNTIFS(Tarefas!$D$5:$D$200,$A7,Tarefas!$G$5:$G$200,I$4) -> 2 | J7: =IF(F7=0,"—",(G7+$F$2*H7)/F7) -> 0.16666667 | K7: Repetições e condições de continuidade/encerramento adequadas (turnos, fim de jogo, desistência)
A8: Organização e manipulação de dados | B8: Obrigatório | C8: 1 | D8: Sim | E8: P2 + P3 | F8: =COUNTIF(Tarefas!$D$5:$D$200,$A8) -> 2 | G8: =COUNTIFS(Tarefas!$D$5:$D$200,$A8,Tarefas!$G$5:$G$200,G$4) -> 0 | H8: =COUNTIFS(Tarefas!$D$5:$D$200,$A8,Tarefas!$G$5:$G$200,H$4) -> 1 | I8: =COUNTIFS(Tarefas!$D$5:$D$200,$A8,Tarefas!$G$5:$G$200,I$4) -> 1 | J8: =IF(F8=0,"—",(G8+$F$2*H8)/F8) -> 0.25 | K8: Estruturas de dados compatíveis com a aplicação (grade, navios, histórico)
A9: Modularização e organização do código | B9: Obrigatório | C9: 1 | D9: Sim | E9: Todos | F9: =COUNTIF(Tarefas!$D$5:$D$200,$A9) -> 2 | G9: =COUNTIFS(Tarefas!$D$5:$D$200,$A9,Tarefas!$G$5:$G$200,G$4) -> 0 | H9: =COUNTIFS(Tarefas!$D$5:$D$200,$A9,Tarefas!$G$5:$G$200,H$4) -> 0 | I9: =COUNTIFS(Tarefas!$D$5:$D$200,$A9,Tarefas!$G$5:$G$200,I$4) -> 2 | J9: =IF(F9=0,"—",(G9+$F$2*H9)/F9) -> 0 | K9: Funções com responsabilidades bem definidas, sem repetição desnecessária
A10: Confiabilidade e tratamento de situações previstas | B10: Obrigatório | C10: 1.5 | D10: Sim | E10: Todos | F10: =COUNTIF(Tarefas!$D$5:$D$200,$A10) -> 6 | G10: =COUNTIFS(Tarefas!$D$5:$D$200,$A10,Tarefas!$G$5:$G$200,G$4) -> 0 | H10: =COUNTIFS(Tarefas!$D$5:$D$200,$A10,Tarefas!$G$5:$G$200,H$4) -> 0 | I10: =COUNTIFS(Tarefas!$D$5:$D$200,$A10,Tarefas!$G$5:$G$200,I$4) -> 6 | J10: =IF(F10=0,"—",(G10+$F$2*H10)/F10) -> 0 | K10: Funciona e trata situações previsíveis (tiro repetido, arquivo corrompido, histórico vazio)
A11: Interface gráfica | B11: Opcional | C11: 1.5 | D11: Sim | E11: P1 | F11: =COUNTIF(Tarefas!$D$5:$D$200,$A11) -> 6 | G11: =COUNTIFS(Tarefas!$D$5:$D$200,$A11,Tarefas!$G$5:$G$200,G$4) -> 0 | H11: =COUNTIFS(Tarefas!$D$5:$D$200,$A11,Tarefas!$G$5:$G$200,H$4) -> 3 | I11: =COUNTIFS(Tarefas!$D$5:$D$200,$A11,Tarefas!$G$5:$G$200,I$4) -> 3 | J11: =IF(F11=0,"—",(G11+$F$2*H11)/F11) -> 0.25 | K11: Interface funcional e integrada às operações do programa
A12: Persistência de dados | B12: Opcional | C12: 1 | D12: Sim | E12: P3 | F12: =COUNTIF(Tarefas!$D$5:$D$200,$A12) -> 4 | G12: =COUNTIFS(Tarefas!$D$5:$D$200,$A12,Tarefas!$G$5:$G$200,G$4) -> 0 | H12: =COUNTIFS(Tarefas!$D$5:$D$200,$A12,Tarefas!$G$5:$G$200,H$4) -> 0 | I12: =COUNTIFS(Tarefas!$D$5:$D$200,$A12,Tarefas!$G$5:$G$200,I$4) -> 4 | J12: =IF(F12=0,"—",(G12+$F$2*H12)/F12) -> 0 | K12: Salvar e recuperar informações entre execuções
A13: Visualização de informações | B13: Opcional | C13: 1 | D13: Sim | E13: P3 + P1 | F13: =COUNTIF(Tarefas!$D$5:$D$200,$A13) -> 6 | G13: =COUNTIFS(Tarefas!$D$5:$D$200,$A13,Tarefas!$G$5:$G$200,G$4) -> 0 | H13: =COUNTIFS(Tarefas!$D$5:$D$200,$A13,Tarefas!$G$5:$G$200,H$4) -> 0 | I13: =COUNTIFS(Tarefas!$D$5:$D$200,$A13,Tarefas!$G$5:$G$200,I$4) -> 6 | J13: =IF(F13=0,"—",(G13+$F$2*H13)/F13) -> 0 | K13: Visualizações corretas e relacionadas aos dados processados
A14: Funcionalidade adicional proposta pela equipe | B14: Opcional | C14: 1.5 | D14: Não | E14: — | F14: =COUNTIF(Tarefas!$D$5:$D$200,$A14) -> 0 | G14: =COUNTIFS(Tarefas!$D$5:$D$200,$A14,Tarefas!$G$5:$G$200,G$4) -> 0 | H14: =COUNTIFS(Tarefas!$D$5:$D$200,$A14,Tarefas!$G$5:$G$200,H$4) -> 0 | I14: =COUNTIFS(Tarefas!$D$5:$D$200,$A14,Tarefas!$G$5:$G$200,I$4) -> 0 | J14: =IF(F14=0,"—",(G14+$F$2*H14)/F14) -> — | K14: Reserva: exige aprovação prévia da professora (pontuação e critérios)
A15: Integração com serviços externos | B15: Opcional | C15: 1.5 | D15: Não | E15: — | F15: =COUNTIF(Tarefas!$D$5:$D$200,$A15) -> 0 | G15: =COUNTIFS(Tarefas!$D$5:$D$200,$A15,Tarefas!$G$5:$G$200,G$4) -> 0 | H15: =COUNTIFS(Tarefas!$D$5:$D$200,$A15,Tarefas!$G$5:$G$200,H$4) -> 0 | I15: =COUNTIFS(Tarefas!$D$5:$D$200,$A15,Tarefas!$G$5:$G$200,I$4) -> 0 | J15: =IF(F15=0,"—",(G15+$F$2*H15)/F15) -> — | K15: Reserva: consulta a API; aumenta o risco de a execução falhar. Não planejada
A17: Obs.: 'Planejado?' (azul) indica se a equipe pretende buscar aquele critério opcional. Os critérios obrigatórios são sempre contados.
